<?xml version="1.0"?>
<robot name="snake_bot">

    <!-- Base Link -->
    <link name="base_link">
        <visual>
            <geometry>
                <cylinder radius="0.03" length="0.07"/>
            </geometry>
            <origin xyz="0 0 0" rpy="0 1.57 0"/>
            <material name="blue">
                <color rgba="0.0 0.0 1.0 1.0"/>
            </material>
        </visual>
    </link>

    <!-- Segment 1 -->
    <joint name="joint1" type="continuous">
        <parent link="base_link"/>
        <child link="link1"/>
        <origin xyz="0.1 0 0" rpy="0 0 0"/>
        <axis xyz="0 0 1"/>
    </joint>

    <link name="link1">
        <visual>
            <geometry>
                <cylinder radius="0.03" length="0.07"/>
            </geometry>
            <origin xyz="0 0 0" rpy="0 1.57 0"/>
            <material name="red">
                <color rgba="1.0 0.0 0.0 1.0"/>
            </material>
        </visual>
    </link>

    <!-- Segment 2 -->
    <joint name="joint2" type="continuous">
        <parent link="link1"/>
        <child link="link2"/>
        <origin xyz="0.1 0 0" rpy="0 0 0"/>
        <axis xyz="0 0 1"/>
    </joint>

    <link name="link2">
        <visual>
            <geometry>
                <cylinder radius="0.03" length="0.07"/>
            </geometry>
            <origin xyz="0 0 0" rpy="0 1.57 0"/>
            <material name="green">
                <color rgba="0.0 1.0 0.0 1.0"/>
            </material>
        </visual>
    </link>

    <!-- Segment 3 -->
    <joint name="joint3" type="continuous">
        <parent link="link2"/>
        <child link="link3"/>
        <origin xyz="0.1 0 0" rpy="0 0 0"/>
        <axis xyz="0 0 1"/>
    </joint>

    <link name="link3">
        <visual>
            <geometry>
                <cylinder radius="0.03" length="0.07"/>
            </geometry>
            <origin xyz="0 0 0" rpy="0 1.57 0"/>
            <material name="yellow">
                <color rgba="1.0 1.0 0.0 1.0"/>
            </material>
        </visual>
    </link>

    <!-- Segment 4 -->
    <joint name="joint4" type="continuous">
        <parent link="link3"/>
        <child link="link4"/>
        <origin xyz="0.1 0 0" rpy="0 0 0"/>
        <axis xyz="0 0 1"/>
    </joint>

    <link name="link4">
        <visual>
            <geometry>
                <cylinder radius="0.03" length="0.07"/>
            </geometry>
            <origin xyz="0 0 0" rpy="0 1.57 0"/>
            <material name="orange">
                <color rgba="1.0 0.5 0.0 1.0"/>
            </material>
        </visual>
    </link>

    <!-- Segment 5 -->
    <joint name="joint5" type="continuous">
        <parent link="link4"/>
        <child link="link5"/>
        <origin xyz="0.1 0 0" rpy="0 0 0"/>
        <axis xyz="0 0 1"/>
    </joint>

    <link name="link5">
        <visual>
            <geometry>
                <cylinder radius="0.03" length="0.07"/>
            </geometry>
            <origin xyz="0 0 0" rpy="0 1.57 0"/>
            <material name="purple">
                <color rgba="0.5 0.0 1.0 1.0"/>
            </material>
        </visual>
    </link>
    <joint name="joint6" type="continuous">
        <parent link="link5"/>
        <child link="link6"/>
        <origin xyz="0.1 0 0" rpy="0 0 0"/>
        <axis xyz="0 0 1"/>
    </joint>

    <link name="link6">
        <visual>
            <geometry>
                <cylinder radius="0.03" length="0.07"/>
            </geometry>
            <origin xyz="0 0 0" rpy="0 1.57 0"/>
            <material name="purple">
                <color rgba="0.5 0.0 1.0 1.0"/>
            </material>
        </visual>
    </link>

</robot>
