<?xml version="1.0"?>
<robot name="snake_bot" xmlns:xacro="http://www.ros.org/wiki/xacro">
    
    <xacro:property name="segment_radius" value="0.03"/>
    <xacro:property name="segment_length" value="0.07"/>
    <xacro:property name="segment_mass" value="0.5"/>

     <material name="Blue">
        <color rgba="0.0 0.0 1.0 1.0"/>
    </material>
    <material name="Red">
        <color rgba="1.0 0.0 0.0 1.0"/>
    </material>
    <material name="Green">
        <color rgba="0.0 1.0 0.0 1.0"/>
    </material>
    <material name="Yellow">
        <color rgba="1.0 1.0 0.0 1.0"/>
    </material>
    <material name="Orange">
        <color rgba="1.0 0.5 0.0 1.0"/>
    </material>
    <material name="Purple">
        <color rgba="0.5 0.0 1.0 1.0"/>
    </material>
    
    <!-- Macro for a single segment -->
    <xacro:macro name="snake_segment" params="parent_link child_link joint_name color">
        <joint name="${joint_name}" type="continuous">
            <parent link="${parent_link}"/>
            <child link="${child_link}"/>
            <origin xyz="0.1 0 0" rpy="0 0 0"/>
            <axis xyz="0 0 1"/>
        </joint>
        
        <link name="${child_link}">
            <inertial>
                <origin xyz="0 0 0"/>
                <mass value="${segment_mass}"/>
                <inertia ixx="0.01" iyy="0.01" izz="0.01" ixy="0.0" ixz="0.0" iyz="0.0"/>
            </inertial>
            <visual>
                <geometry>
                    <cylinder radius="${segment_radius}" length="${segment_length}"/>
                </geometry>
                <origin xyz="0 0 0" rpy="0 1.57 0"/>
                <material name="${color}">
                    <color rgba="1.0 1.0 1.0 1.0"/>
                </material>
            </visual>
            <collision>
                <geometry>
                    <cylinder radius="${segment_radius}" length="${segment_length}"/>
                </geometry>
            </collision>
        </link>
    </xacro:macro>

    <!-- Base Link -->
    <link name="base_link">
        <inertial>
            <origin xyz="0 0 0"/>
            <mass value="1.0"/>
            <inertia ixx="0.1" iyy="0.1" izz="0.1" ixy="0.0" ixz="0.0" iyz="0.0"/>
        </inertial>
        <visual>
            <geometry>
                <cylinder radius="${segment_radius}" length="${segment_length}"/>
            </geometry>
            <origin xyz="0 0 0" rpy="0 1.57 0"/>
            <material name="blue">
                <color rgba="0.0 0.0 1.0 1.0"/>
            </material>
        </visual>
        <collision>
            <geometry>
                <cylinder radius="${segment_radius}" length="${segment_length}"/>
            </geometry>
        </collision>
    </link>
    
    <!-- Adding Snake Segments -->
    <xacro:snake_segment parent_link="base_link" child_link="link1" joint_name="joint1" color="Purple"/>
    <xacro:snake_segment parent_link="link1" child_link="link2" joint_name="joint2" color="Red"/>
    <xacro:snake_segment parent_link="link2" child_link="link3" joint_name="joint3" color="Green"/>
    <xacro:snake_segment parent_link="link3" child_link="link4" joint_name="joint4" color="Yellow"/>
    <xacro:snake_segment parent_link="link4" child_link="link5" joint_name="joint5" color="Orange"/>
    <xacro:snake_segment parent_link="link5" child_link="link6" joint_name="joint6" color="Blue"/>
    
</robot>